<mujoco model="wheel_legged_robot_v0.2">

    <compiler angle="radian" coordinate="local" inertiafromgeom="auto"/>

    <option gravity="0 0 -9.81" timestep="0.00001" collision="predefined" cone="elliptic" o_solref="0.002 0.1">
        <flag override="enable"/>
    </option>

    <visual>
    </visual>

    <asset>
        <texture type="skybox" builtin="gradient" width="100" height="100" rgb1="0.4 0.6 0.8" rgb2="0 0 0"/>
        <texture type="2d" name="plane" builtin="checker" rgb1="0.2 0.2 0.2" rgb2="0.3 0.3 0.3" width="100"
                 height="100"/>
        <material name="plane" reflectance="0.0" texture="plane" texrepeat="1 1" texuniform="true"/>
        <texture type="2d" name="wheel" builtin="checker" rgb1="0.8 0.6 0.2" rgb2="0.2 0.6 0.8" width="100"
                 height="100"/>
        <material name="wheel" reflectance="0.0" texture="wheel" texrepeat="1 1" texuniform="true"/>
    </asset>

    <!-- build the robot model,  SI unit-->
    <worldbody>
        <!-- define the environment and optical environment -->
        <light mode="trackcom" pos="0 0 5" dir="0 0 -1"/>
        <light directional="true" pos="0 0 10" dir="0 0 -1" diffuse="0.2 0.2 0.2" specular="0 0 0"/>
        <geom name="floor" pos="0 0 0" size="50 50 50" type="plane" material="plane" condim="3" conaffinity="15"/>

        <!-- robot part -->
        <!-- torso part -->
        <body name="torso" pos="0 0 0.515">
            <camera name="track" pos="0 -0.3 0.3" zaxis="0 -1 0.5" mode="track"/>
            <geom type="box" rgba="0.992 0.576 0.588 1" name="torso_geom" pos="0.05 0 0.103" size="0.175 0.15 0.103"
                  mass="0.05"/>
            <geom name="battery" type="cylinder" rgba="0.992 0.576 0.588 1" pos="0 0 0" fromto="0 -0.15 0 0 0.15 0"
                  mass="10" size="0.1"/>
            <joint name="root_x" type="slide" axis="1 0 0" pos="0 0 0" limited="false" damping="0" stiffness="0"
                   armature="0"/>
            <joint name="root_z" type="slide" axis="0 0 1" pos="0 0 0" limited="false" damping="0" stiffness="0"
                   armature="0"/>
            <joint name="rotation_y" type="hinge" axis="0 1 0" pos="0 0 0" limited="false" damping="0" stiffness="0"
                   armature="0"/>


            <!--left leg part-->
            <body name="L_link1" pos="0 0.15 0">
                <geom name="L_link1" type="capsule" pos="0 0 0" fromto="0 0 0 -0.196 0 -0.2026" rgba="0.686 1 0.616 1"
                      size="0.01" mass="0.01"/>
                <joint name="L_leg" type="hinge" axis="0 1 0" pos="0 0 0" limited="false" damping="0" armature="0"
                       stiffness="0"/>
                <body name="L_link3" pos="-0.196 0 -0.2026">
                    <geom name="L_link3" type="capsule" pos="0 0 0" fromto="0.193 0 -0.207 -0.047 0 0.05"
                          rgba="0.686 1 0.616 1" size="0.01" mass="0.01"/>
                    <joint name="L_1_3" type="hinge" pos="0 0 0" axis="0 1 0" limited="false" stiffness="0" armature="0"
                           damping="0"/>
                    <body name="L_wheel" pos="0.193 0 -0.207">
                        <geom name="L_wheel" pos="0 0 0" type="cylinder" fromto="0 -0.02 0 0 0.02 0" size="0.103"
                              rgba="1 0.945 0.620 1" mass="0.1" material="wheel"/>
                        <joint name="L_wheel" type="hinge" axis="0 1 0" pos="0 0 0" limited="false" damping="0"
                               armature="0" stiffness="0"/>
                    </body>
                </body>
            </body>
            <body name="L_link2" pos="-0.1 0.15 0.1015">
                <geom name="L_link2" pos="0 0 0" type="capsule" fromto="0 0 0 -0.1436 0 -0.253" size="0.01"
                      rgba="0.686 1 0.616 1" mass="0.01"/>
                <joint name="torso_L_link2" type="hinge" pos="0 0 0" axis="0 1 0" limited="false" stiffness="0"
                       armature="0" damping="0"/>
            </body>

            <!--right leg part-->
            <body name="R_link1" pos="0 -0.15 0">
                <geom name="R_link1" type="capsule" pos="0 0 0" fromto="0 0 0 -0.196 0 -0.2026" rgba="0.686 1 0.616 1"
                      size="0.01" mass="0.01"/>
                <joint name="R_leg" type="hinge" axis="0 1 0" pos="0 0 0" limited="false" damping="0" armature="0"
                       stiffness="0"/>
                <body name="R_link3" pos="-0.196 0 -0.2026">
                    <geom name="R_link3" type="capsule" pos="0 0 0" fromto="0.193 0 -0.207 -0.047 0 0.05"
                          rgba="0.686 1 0.616 1" size="0.01" mass="0.01"/>
                    <joint name="R_1_3" type="hinge" pos="0 0 0" axis="0 1 0" limited="false" stiffness="0" armature="0"
                           damping="0"/>
                    <body name="R_wheel" pos="0.193 0 -0.207">
                        <geom name="R_wheel" pos="0 0 0" type="cylinder" fromto="0 -0.02 0 0 0.02 0" size="0.103"
                              rgba="1 0.945 0.620 1" mass="0.1" material="wheel"/>
                        <joint name="R_wheel" type="hinge" axis="0 1 0" pos="0 0 0" limited="false" damping="0"
                               armature="0" stiffness="0"/>
                    </body>
                </body>
            </body>
            <body name="R_link2" pos="-0.1 -0.15 0.1015">
                <geom name="R_link2" pos="0 0 0" type="capsule" fromto="0 0 0 -0.1436 0 -0.253" size="0.01"
                      rgba="0.686 1 0.616 1" mass="0.01"/>
                <joint name="torso_R_link2" type="hinge" pos="0 0 0" axis="0 1 0" limited="false" stiffness="0"
                       armature="0" damping="0"/>
            </body>


        </body>

    </worldbody>

    <!-- define constraint -->
    <equality>
        <connect name="L_link_constraint" active="true" solref="0.002 1" body1="L_link3" body2="L_link2"
                 anchor="-0.047 0 0.05"/>
        <connect name="R_link_constraint" active="true" solref="0.002 1" body1="R_link3" body2="R_link2"
                 anchor="-0.047 0 0.05"/>
    </equality>

    <!-- define actuator -->
    <actuator>
        <!--motor joint="L_leg" gear="1" name="L_leg"/-->
        <position joint="L_leg" gear="10" kp="100" name="L_leg"/>
        <motor joint="L_wheel" gear="1" name="L_wheel"/>
        <!--motor joint="R_leg" gear="1" name="R_leg"/-->
        <position joint="R_leg" gear="10" kp="100" name="R_leg"/>
        <motor joint="R_wheel" gear="1" name="R_wheel"/>
        <motor joint="root_x" gear="1" name="external"/>
    </actuator>

    <!-- contact define -->
    <contact>
        <pair geom1="floor" geom2="L_wheel" condim="3" friction="0.5 0.5 0.5" solref="0.02 0.1"/>
        <pair geom1="floor" geom2="R_wheel" condim="3" friction="0.5 0.5 0.5" solref="0.02 0.1"/>
    </contact>


</mujoco>